<?xml version="1.0"?>
<robot name="my_robot">
    <!--first link-->

    <gazebo reference="top_drive_1">
        <material>Gazebo/Red</material>
    </gazebo>
<gazebo reference="top_drive_2">
        <material>Gazebo/Red</material>
    </gazebo>
    <gazebo reference="derrick_1">
        <material>Gazebo/Grey</material>
    </gazebo>

<gazebo reference="derrick_rail">
        <material>Gazebo/Grey</material>
    </gazebo>

    <gazebo reference="derrick_rail">
        <material>Gazebo/Black</material>
    </gazebo>


    <!-- ros_control plugin -->
    <gazebo>
        <plugin name="gazebo_ros_control" filename="libgazebo_ros_control.so">
            <robotNamespace>/my_robot</robotNamespace>
            <robotSimType>gazebo_ros_control/DefaultRobotHWSim</robotSimType>
        </plugin>
    </gazebo>

    <!--1st link - main leg of the derrick-->
    <link name="derrick_1">
        <!--         <pose> 0 0 0 0 0 0 </pose>-->
        <inertial>
            <origin xyz="0.0 0.0 0.0" rpy="0.0 0.0 0.0"/>
            <mass value="1"/>
            <!--inertia ixx="23.075" ixy="0" ixz="0" iyy="23.075" iyz="0.0" izz="0.00002168"/>-->
            <inertia ixx="0.1" ixy="0.3" ixz="0.5" iyy="0.0" iyz="0.0" izz="0.0"/>
        </inertial>
        <!--         <visual name="">-->
        <visual>
            <origin xyz="0.0 0.0 10" rpy="0.0 0.0 0.0"/>
            <!-- 3 m offset-->
            <!-- try to fix the tf; the derrick touches ground at z = 8.32, or 7 m for 14 m height 
            So offset by 3.3 m  -->
            <geometry>
                <!--box size="0.1 0.1 16.64"/>-->
                <box size="0.1 0.1 14"/>
                <!--cylinder radius="3" length="10"/>-->
            </geometry>
            <!-- <material name="">
                <color rgba="1.0 0.0 0.0 1.0"/>
            </material> -->
        </visual>
        <collision>
            <origin xyz="0.0 0.0 10" rpy="0.0 0.0 0.0"/>
            <geometry>
                <box size="0.1 0.1 14"/>
            </geometry>
        </collision>
    </link>

    <!--2nd derrick-->
    <link name="derrick_2">
        <!--         <pose> 0 0 0 0 0 0 </pose>-->
        <inertial>
            <origin xyz="0.0 0.0 0.0" rpy="0.0 0.0 0.0"/>
            <mass value="1"/>
            <!--inertia ixx="23.075" ixy="0" ixz="0" iyy="23.075" iyz="0.0" izz="0.00002168"/>-->
            <inertia ixx="0.1" ixy="0.3" ixz="0.5" iyy="0.0" iyz="0.0" izz="0.0"/>
        </inertial>
        <!--         <visual name="">-->
        <visual>
            <origin xyz="0.0 0.0 10" rpy="0.0 0.0 0.0"/>
            <!-- 3 m offset-->
            <!-- try to fix the tf; the derrick touches ground at z = 8.32, or 7 m for 14 m height 
            So offset by 3.3 m  -->
            <geometry>
                <!--box size="0.1 0.1 16.64"/>-->
                <box size="0.1 0.1 14"/>
                <!--cylinder radius="3" length="10"/>-->
            </geometry>
            <!-- <material name="">
                <color rgba="1.0 0.0 0.0 1.0"/>
            </material> -->
        </visual>
        <collision>
            <origin xyz="0.0 0.0 10" rpy="0.0 0.0 0.0"/>
            <geometry>
                <box size="0.1 0.1 14"/>
            </geometry>
        </collision>
    </link>

    <link name="derrick_cross1">
        <!--         <pose> 0 0 0 0 0 0 </pose>-->
        <inertial>
            <origin xyz="0 0.0 0.0" rpy="0.0 0.0 0"/>
            <mass value="1"/>
            <!--inertia ixx="23.075" ixy="0" ixz="0" iyy="23.075" iyz="0.0" izz="0.00002168"/>-->
            <inertia ixx="0.1" ixy="0.3" ixz="0.5" iyy="0.0" iyz="0.0" izz="0.0"/>
        </inertial>
        <!--         <visual name="">-->
        <visual>
            <origin xyz="0 0.0 10" rpy="0.0 0.0 0.0"/>
            <!-- 3 m offset-->
            <!-- try to fix the tf; the derrick touches ground at z = 8.32, or 7 m for 14 m height 
            So offset by 3.3 m  -->
            <geometry>
                <!--box size="0.1 0.1 16.64"/>-->
                <box size="0.1 0.1 14.1718"/>
                <!-- use pythagorean for z-->
                <!--cylinder radius="3" length="10"/>-->
            </geometry>
            <!-- <material name="">
                <color rgba="1.0 0.0 0.0 1.0"/>
            </material> -->
        </visual>
        <collision>
            <origin xyz="0 0.0 10" rpy="0.0 0.0 0.0"/>
            <geometry>
                <box size="0.1 0.1 14.1718"/>
            </geometry>
        </collision>
    </link>

    <link name="derrick_cross2">
        <inertial>
            <origin xyz="0 0.0 0.0" rpy="0.0 0.0 0"/>
            <mass value="1"/>
            <inertia ixx="0.1" ixy="0.3" ixz="0.5" iyy="0.0" iyz="0.0" izz="0.0"/>
        </inertial>
        <visual>
            <origin xyz="0 0.0 10" rpy="0.0 0.0 0.0"/>
            <geometry>
                <box size="0.1 0.1 14.1718"/>
                <!-- use pythagorean for z-->
            </geometry>
        </visual>
        <collision>
            <origin xyz="0 0.0 10" rpy="0.0 0.0 0.0"/>
            <geometry>
                <box size="0.1 0.1 14.1718"/>
            </geometry>
        </collision>
    </link>

    <!-- change the inertial properties for the cylinder when using actual drill pipe -->
    <link name="derrick_rail">
        <!--         <pose> 0 0 0 0 0 0 </pose>-->
        <inertial>
            <origin xyz="0.0 0.0 0.0" rpy="0.0 0.0 0.0"/>
            <mass value="1"/>
            <inertia ixx="0.1" ixy="0.3" ixz="0.5" iyy="0.0" iyz="0.0" izz="0.0"/>
        </inertial>
        <!--         <visual name="">-->
        <visual>
            <origin xyz="0.0 0.0 0" rpy="0.0 0.0 0.0"/>
            <!-- 3 m offset-->
            <geometry>
                <box size="0.5 0.1 9.5"/>
            </geometry>
            <!-- <material name="">
                <color rgba="1.0 0.0 0.0 1.0"/>
            </material> -->
        </visual>
        <collision>
            <origin xyz="0.0 0.0 0" rpy="0.0 0.0 0.0"/>
            <geometry>
                <box size="0.5 0.1 13"/>
            </geometry>
        </collision>
    </link>

    <link name="derrick_3">
        <!--         <pose> 0 0 0 0 0 0 </pose>-->
        <inertial>
            <origin xyz="0.0 0.0 0.0" rpy="0.0 0.0 0.0"/>
            <mass value="1"/>
            <!--inertia ixx="23.075" ixy="0" ixz="0" iyy="23.075" iyz="0.0" izz="0.00002168"/>-->
            <inertia ixx="0.1" ixy="0.3" ixz="0.5" iyy="0.0" iyz="0.0" izz="0.0"/>
        </inertial>
        <!--         <visual name="">-->
        <visual>
            <origin xyz="0.0 0.0 10" rpy="0.0 0.0 0.0"/>
            <!-- 3 m offset-->
            <!-- try to fix the tf; the derrick touches ground at z = 8.32, or 7 m for 14 m height 
            So offset by 3.3 m  -->
            <geometry>
                <!--box size="0.1 0.1 16.64"/>-->
                <box size="0.1 0.1 14"/>
                <!--cylinder radius="3" length="10"/>-->
            </geometry>
            <!-- <material name="">
                <color rgba="1.0 0.0 0.0 1.0"/>
            </material> -->
        </visual>
        <collision>
            <origin xyz="0.0 0.0 10" rpy="0.0 0.0 0.0"/>
            <geometry>
                <box size="0.1 0.1 14"/>
            </geometry>
        </collision>
    </link>

    <link name="derrick_4">
        <!--         <pose> 0 0 0 0 0 0 </pose>-->
        <inertial>
            <origin xyz="0.0 0.0 0.0" rpy="0.0 0.0 0.0"/>
            <mass value="1"/>
            <!--inertia ixx="23.075" ixy="0" ixz="0" iyy="23.075" iyz="0.0" izz="0.00002168"/>-->
            <inertia ixx="0.1" ixy="0.3" ixz="0.5" iyy="0.0" iyz="0.0" izz="0.0"/>
        </inertial>
        <!--         <visual name="">-->
        <visual>
            <origin xyz="0.0 0.0 10" rpy="0.0 0.0 0.0"/>
            <!-- 3 m offset-->
            <!-- try to fix the tf; the derrick touches ground at z = 8.32, or 7 m for 14 m height 
            So offset by 3.3 m  -->
            <geometry>
                <!--box size="0.1 0.1 16.64"/>-->
                <box size="0.1 0.1 14"/>
                <!--cylinder radius="3" length="10"/>-->
            </geometry>
            <!-- <material name="">
                <color rgba="1.0 0.0 0.0 1.0"/>
            </material> -->
        </visual>
        <collision>
            <origin xyz="0.0 0.0 10" rpy="0.0 0.0 0.0"/>
            <geometry>
                <box size="0.1 0.1 14"/>
            </geometry>
        </collision>
    </link>

    <link name="derrick_cross3">
        <inertial>
            <origin xyz="0 0.0 0.0" rpy="0.0 0.0 0"/>
            <mass value="1"/>
            <inertia ixx="0.1" ixy="0.3" ixz="0.5" iyy="0.0" iyz="0.0" izz="0.0"/>
        </inertial>
        <visual>
            <origin xyz="0 0.0 10" rpy="0.0 0.0 0.0"/>
            <geometry>
                <box size="0.1 0.1 14.1718"/>
                <!-- use pythagorean for z-->
            </geometry>
        </visual>
        <collision>
            <origin xyz="0 0.0 10" rpy="0.0 0.0 0.0"/>
            <geometry>
                <box size="0.1 0.1 14.1718"/>
            </geometry>
        </collision>
    </link>

    <link name="derrick_cross4">
        <inertial>
            <origin xyz="0 0.0 0.0" rpy="0.0 0.0 0"/>
            <mass value="1"/>
            <inertia ixx="0.1" ixy="0.3" ixz="0.5" iyy="0.0" iyz="0.0" izz="0.0"/>
        </inertial>
        <visual>
            <origin xyz="0 0.0 10" rpy="0.0 0.0 0.0"/>
            <geometry>
                <box size="0.1 0.1 14.1718"/>
                <!-- use pythagorean for z-->
            </geometry>
        </visual>
        <collision>
            <origin xyz="0 0.0 10" rpy="0.0 0.0 0.0"/>
            <geometry>
                <box size="0.1 0.1 14.1718"/>
            </geometry>
        </collision>
    </link>

    <link name="derrick_cross5">
        <inertial>
            <origin xyz="0 0.0 0.0" rpy="0.0 0.0 0"/>
            <mass value="1"/>
            <inertia ixx="0.1" ixy="0.3" ixz="0.5" iyy="0.0" iyz="0.0" izz="0.0"/>
        </inertial>
        <visual>
            <origin xyz="0 0.0 10" rpy="0.0 0.0 0.0"/>
            <geometry>
                <box size="0.1 0.1 14.1718"/>
                <!-- use pythagorean for z-->
            </geometry>
        </visual>
        <collision>
            <origin xyz="0 0.0 10" rpy="0.0 0.0 0.0"/>
            <geometry>
                <box size="0.1 0.1 14.1718"/>
            </geometry>
        </collision>
    </link>

    <link name="derrick_cross6">
        <inertial>
            <origin xyz="0 0.0 0.0" rpy="0.0 0.0 0"/>
            <mass value="1"/>
            <inertia ixx="0.1" ixy="0.3" ixz="0.5" iyy="0.0" iyz="0.0" izz="0.0"/>
        </inertial>
        <visual>
            <origin xyz="0 0.0 10" rpy="0.0 0.0 0.0"/>
            <geometry>
                <box size="0.1 0.1 14.1718"/>
                <!-- use pythagorean for z-->
            </geometry>
        </visual>
        <collision>
            <origin xyz="0 0.0 10" rpy="0.0 0.0 0.0"/>
            <geometry>
                <box size="0.1 0.1 14.1718"/>
            </geometry>
        </collision>
    </link>

    <!-- Topdrive link -->
    <link name="top_drive_1">
        <!--         <pose> 0 0 0 0 0 0 </pose>-->
        <inertial>
            <origin xyz="0.0 0.0 0.0" rpy="0.0 0.0 0.0"/>
            <mass value="1"/>
            <inertia ixx="0.1" ixy="0.3" ixz="0.5" iyy="0.0" iyz="0.0" izz="0.0"/>

        </inertial>
        <!--         <visual name="">-->
        <visual>
            <origin xyz="0.0 0.0 0" rpy="0.0 0.0 0.0"/>
            <geometry>
                <box size="1 1 3"/>
                <!--cylinder radius="3" length="10"/>-->
            </geometry>
            <material name="">
                <color rgba="1.0 0.0 0.0 1.0"/>
            </material>
        </visual>
        <collision>
            <origin xyz="0.0 0.0 0" rpy="0.0 0.0 0.0"/>
            <geometry>
                <box size="1 1 3"/>
            </geometry>
        </collision>
    </link>

    <link name="top_drive_2">
        <!-- <pose> 0 0 0 0 0 0 </pose>-->
        <inertial>
            <origin xyz="0.0 0.0 0.0" rpy="0.0 0.0 0.0"/>
            <mass value="1"/>
            <inertia ixx="0.1" ixy="0.3" ixz="0.5" iyy="0.0" iyz="0.0" izz="0.0"/>
        </inertial>
        <visual>
            <origin xyz="0.0 0.0 0" rpy="0.0 0.0 0.0"/>
            <geometry>
                <box size="0.5 0.5 1"/>
                <!--cylinder radius="3" length="10"/>-->
            </geometry>
            <material name="">
                <color rgba="1.0 0.0 0.0 1.0"/>
            </material>
        </visual>
        <collision>
            <origin xyz="0.0 0.0 0" rpy="0.0 0.0 0.0"/>
            <geometry>
                <box size="0.5 0.5 1"/>
            </geometry>
        </collision>
    </link>

<link name="iron_roughneck">
        <!-- <pose> 0 0 0 0 0 0 </pose>-->
        <inertial>
            <origin xyz="0.0 0.0 0.0" rpy="0.0 0.0 0.0"/>
            <mass value="1"/>
            <inertia ixx="0.1" ixy="0.3" ixz="0.5" iyy="0.0" iyz="0.0" izz="0.0"/>
        </inertial>
        <visual>
            <origin xyz="0.0 0.0 0" rpy="0.0 0.0 0.0"/>
            <geometry>
                <box size="0.3 0.5 1"/>
                <!--cylinder radius="3" length="10"/>-->
            </geometry>
            <material name="">
                <color rgba="1.0 0.0 0.0 1.0"/>
            </material>
        </visual>
        <collision>
            <origin xyz="0.0 0.0 0" rpy="0.0 0.0 0.0"/>
            <geometry>
                <box size="0.3 0.5 1"/>
            </geometry>
        </collision>
    </link>

    <!--6th link - #drillpipe-->
    <link name="drillpipe">
        <!-- <pose> 0 0 0 0 0 0 </pose>-->
        <inertial>
            <origin xyz="0.0 0.0 0.0" rpy="0.0 0.0 0.0"/>
            <mass value="0.5"/>
            <inertia ixx="0.1" ixy="0.3" ixz="0.5" iyy="0.0" iyz="0.0" izz="0.0"/>
        </inertial>
        <!-- <visual name="">-->
        <visual>
            <origin xyz="0.0 0.0 0" rpy="0.0 0.0 0.0"/>
            <geometry>
                <!--box size="1.0 1.0 1.0"/>-->
                <cylinder radius="0.127" length="4.5"/>
            </geometry>
            <material name="">
                <color rgba="0.0 0.0 0.0 0.8"/>
            </material>
        </visual>
        <collision>
            <origin xyz="0.0 0.0 0.0" rpy="0.0 0.0 0.0"/>
            <geometry>
                <box size="1.0 1.0 1.0"/>
            </geometry>
        </collision>
    </link>

    <!--7th link - #drillbit-->
    <link name="drillbit">
        <!-- <pose> 0 0 0 0 0 0 </pose>-->
        <inertial>
            <origin xyz="0.0 0.0 0.0" rpy="0.0 0.0 0.0"/>
            <mass value="0.5"/>
            <inertia ixx="0.1" ixy="0.3" ixz="0.5" iyy="0.0" iyz="0.0" izz="0.0"/>
        </inertial>
        <!-- <visual name="">-->
        <visual>
            <origin xyz="0.0 0.0 0" rpy="0.0 0.0 0.0"/>
            <geometry>
                <box size="0.3 0.3 0.1"/>
                <!--cylinder radius="0.127" length="9"/>-->
            </geometry>
            <material name="">
                <color rgba="0.0 0.0 0.0 0.8"/>
            </material>
        </visual>
        <collision>
            <origin xyz="0.0 0.0 0.0" rpy="0.0 0.0 0.0"/>
            <geometry>
                <box size="0.3 0.3 0.3"/>
            </geometry>
        </collision>
    </link>

    <link name="camera">
        <collision>
            <origin xyz="0 0 0" rpy="0 0 0"/>
            <geometry>
                <!--<box size="${cameraSize} ${cameraSize} ${cameraSize}"/>-->
                <!--https://github.com/richardw05/mybot_ws/blob/master/src/mybot_description/urdf/mybot.xacro -->
                <box size="0.05 0.05 0.05"/>
            </geometry>
        </collision>

        <visual>
            <origin xyz="0 0 0" rpy="0 0 0"/>
            <geometry>
                <box size=" 0.05 0.05 0.05"/>
            </geometry>
            <material name="green"/>
        </visual>

        <inertial>
            <mass value="0.1" />
            <origin xyz="0 0 0" rpy="0 0 0"/>
            <box_inertia m="0.1" x="0.01" y="0.01" z="0.01" />
            <inertia ixx="1e-6" ixy="0" ixz="0" iyy="1e-6" iyz="0" izz="1e-6" />
        </inertial>
    </link>

    <joint name="camera_joint" type="fixed">
        <axis xyz="5 5 20" />
        <origin xyz="1.1 5.1 4" rpy="0 0.785 1.570796327"/>
        <!-- try to flip this to face the derrick, and put in the same axis as drill pipe-->
        <parent link="derrick_1"/>
        <child link="camera"/>
    </joint>

    <gazebo reference="camera">
        <material>Gazebo/Green</material>
        <sensor type="camera" name="camera1">
            <update_rate>30.0</update_rate>
            <camera name="head">
                <horizontal_fov>1.3962634</horizontal_fov>
                <image>
                <!--height, width = 800-->
                    <width>1000</width>
                    <height>1000</height>
                    <format>R8G8B8</format>
                </image>
                <clip>
                    <near>0.02</near>
                    <far>300</far>
                </clip>
            </camera>
            <plugin name="camera_controller" filename="libgazebo_ros_camera.so">
                <alwaysOn>true</alwaysOn>
                <updateRate>0.0</updateRate>
                <cameraName>my_robot/camera1</cameraName>                <!--change this when you add new camera-->
                <imageTopicName>image_raw</imageTopicName>
                <cameraInfoTopicName>camera_info</cameraInfoTopicName>
                <frameName>camera</frameName>
                <hackBaseline>0.07</hackBaseline>
                <distortionK1>0.0</distortionK1>
                <distortionK2>0.0</distortionK2>
                <distortionK3>0.0</distortionK3>
                <distortionT1>0.0</distortionT1>
                <distortionT2>0.0</distortionT2>
            </plugin>
        </sensor>
    </gazebo>


    <joint name="joint1" type="prismatic">
        <axis xyz="0 0 1"/>
        <origin xyz="1.1 0.6 14.5" rpy="0.0 0.0 0.0"/> <!--was 14.5-->
        <!--0.05 + 0.5 m from edge of derrick, (0.55+0.05 in y)-->
        <!-- x is relative to child link origin-->
        <parent link="derrick_1"/>
        <!--if you change the parent, change it in the .rviz file -->
        <!-- I think you can change the derrick leg independent of the topdrive position-->
        <child link="top_drive_1"/>
        <!--limit effort below is only for the prismatic joint-->
        <limit effort="1000.0" lower="-4.7" upper="4.6" velocity="0.5"/>
        <!-- upper limit is 2 m less than 16.64-->
    </joint>

    <joint name="joint2" type="fixed">
        <axis xyz="0 0 1"/>
        <origin xyz="1.1 0.05 12" rpy="0.0 0.0 0.0"/>
        <!-- 2.5 m above ground; in x = 0.25+0.1(match td) + 0.25 (TD center) + 0.5 (TD X offset)-->
        <!-- x is relative to child link origin-->
        <parent link="derrick_1"/>
        <!--if you change the parent, change it in the .rviz file -->
        <!-- I think you can change the derrick leg independent of the topdrive position-->
        <child link="derrick_rail"/>
        <!--limit effort below is only for the prismatic joint-->
        <limit effort="1000.0" lower="-14.64" upper="0" velocity="0.5"/>
        <!-- upper limit is 2 m less than 16.64-->
    </joint>


    <joint name="joint3" type="fixed">
        <axis xyz="0 0 0"/>
        <origin xyz="-0.5 0 0.3" rpy="0 0.155868201 0"/>
        <!-- 2.5 m above ground; in x = 0.25+0.1(match td) + 0.25 (TD center) + 0.5 (TD X offset)-->
        <!-- x is relative to child link origin-->
        <parent link="derrick_1"/>
        <!--if you change the parent, change it in the .rviz file -->
        <!-- I think you can change the derrick leg independent of the topdrive position-->
        <child link="derrick_cross1"/>
        <!--limit effort below is only for the prismatic joint-->
        <limit effort="1000.0" lower="-14.64" upper="0" velocity="0.5"/>
        <!-- upper limit is 2 m less than 16.64-->
    </joint>

    <joint name="joint4" type="continuous">
        <axis xyz="0 0 1"/>
        <origin xyz="0 0 -4.25" rpy="0.0 0.0 0.0"/> <!--initially -6 in z = 9/2-->
        <parent link="top_drive_1"/>
        <child link="drillpipe"/>
        <!--limit effort below is only for the prismatic joint-->
        <limit effort="1000.0" lower="0" upper="10" velocity="10"/>
    </joint>

    <joint name="joint5" type="fixed">
        <axis xyz="0 0 1"/>
        <origin xyz="2.2 0.0 0" rpy="0.0 0.0 0.0"/>
        <!-- 2.5 m above ground; in x = 0.25+0.1(match td) + 0.25 (TD center) + 0.5 (TD X offset)-->
        <!-- x is relative to child link origin-->
        <parent link="derrick_1"/>
        <child link="derrick_2"/>
        <limit effort="1000.0" lower="-14.64" upper="0" velocity="0.5"/>
    </joint>

    <joint name="joint6" type="fixed">
        <axis xyz="0 0 0"/>
        <origin xyz="0.5 0 0.3" rpy="0 -0.155868201 0"/>
        <!-- 2.5 m above ground; in x = 0.25+0.1(match td) + 0.25 (TD center) + 0.5 (TD X offset)-->
        <!-- x is relative to child link origin-->
        <parent link="derrick_2"/>
        <!--if you change the parent, change it in the .rviz file -->
        <!-- I think you can change the derrick leg independent of the topdrive position-->
        <child link="derrick_cross2"/>
        <!--limit effort below is only for the prismatic joint-->
        <limit effort="1000.0" lower="-14.64" upper="0" velocity="0.5"/>
        <!-- upper limit is 2 m less than 16.64-->
    </joint>
    <joint name="joint7" type="fixed">
        <axis xyz="0 0 1"/>
        <origin xyz="2.2 1.2 0" rpy="0.0 0.0 0.0"/>
        <parent link="derrick_1"/>
        <child link="derrick_3"/>
        <limit effort="1000.0" lower="-14.64" upper="0" velocity="0.5"/>
    </joint>

    <joint name="joint8" type="fixed">
        <axis xyz="0 0 1"/>
        <origin xyz="0 1.2 0" rpy="0.0 0.0 0.0"/>
        <parent link="derrick_1"/>
        <child link="derrick_4"/>
        <limit effort="1000.0" lower="-14.64" upper="0" velocity="0.5"/>
    </joint>

    <joint name="joint9" type="fixed">
        <axis xyz="0 0 0"/>
        <origin xyz="0 -0.3 0.3" rpy="-0.085505294 0 0"/>
        <parent link="derrick_2"/>
        <child link="derrick_cross3"/>
        <limit effort="1000.0" lower="-14.64" upper="0" velocity="0.5"/>
    </joint>

    <joint name="joint10" type="fixed">
        <axis xyz="0 0 0"/>
        <origin xyz="0 0.3 0.3" rpy="0.085505294 0 0"/>
        <parent link="derrick_3"/>
        <child link="derrick_cross4"/>
        <limit effort="1000.0" lower="-14.64" upper="0" velocity="0.5"/>
    </joint>

    <joint name="joint11" type="fixed">
        <axis xyz="0 0 0"/>
        <origin xyz="-0.5 0 0.3" rpy="0 0.155868201 0"/>
        <parent link="derrick_4"/>
        <child link="derrick_cross5"/>
        <limit effort="1000.0" lower="-14.64" upper="0" velocity="0.5"/>
    </joint>

<!---0.5 0 0.3" rpy="0 0.155868201 0"/>-->
    <joint name="joint12" type="fixed">
        <axis xyz="0 0 0"/>
        <origin xyz="0.3 0 0.3" rpy="0 -0.155868201 0"/>
        <parent link="derrick_3"/>
        <child link="derrick_cross6"/>
        <limit effort="1000.0" lower="-14.64" upper="0" velocity="0.5"/>
    </joint>

    <joint name="joint13" type="fixed">
        <axis xyz="0 0 1"/>
        <origin xyz="0 0 -2.25" rpy="0.0 0.0 0.0"/> <!--initially 4.5-->
        <parent link="drillpipe"/>
        <child link="drillbit"/>
    </joint>

 <joint name="joint14" type="fixed">
        <axis xyz="0 0 1"/>
        <origin xyz="0 0 -1.5" rpy="0.0 0.0 0.0"/>
        <parent link="top_drive_1"/>
        <child link="top_drive_2"/>
    </joint>

 <joint name="joint15" type="prismatic">
        <axis xyz="0 1 0"/>
        <origin xyz="1.1 -1.05 3.5" rpy="0.0 0.0 0.0"/>
        <!-- 2.5 m above ground; in x = 0.25+0.1(match td) + 0.25 (TD center) + 0.5 (TD X offset)-->
        <!-- x is relative to child link origin-->
        <parent link="derrick_1"/>
        <!--if you change the parent, change it in the .rviz file -->
        <!-- I think you can change the derrick leg independent of the topdrive position-->
        <child link="iron_roughneck"/>
        <!--limit effort below is only for the prismatic joint-->
        <limit effort="1000.0" lower="-2.64" upper="0" velocity="0.5"/>
        <!-- upper limit is 2 m less than 16.64-->
    </joint>

    <transmission name="tran1">
        <type>transmission_interface/SimpleTransmission</type>
        <joint name="joint1">
            <hardwareInterface>hardware_interface/EffortJointInterface</hardwareInterface>
        </joint>        <!--using position joint interface now for the topdrive position-->
        <actuator name="motor1">
            <hardwareInterface>hardware_interface/EffortJointInterface</hardwareInterface>
            <mechanicalReduction>1</mechanicalReduction>
        </actuator>
    </transmission>

    <!-- drill pipe controller -->

<transmission name="tran2">
    <type>transmission_interface/SimpleTransmission</type>
    <joint name="joint4">
      <hardwareInterface>hardware_interface/EffortJointInterface</hardwareInterface>
    </joint>
    <actuator name="motor2">
      <hardwareInterface>hardware_interface/EffortJointInterface</hardwareInterface>
      <mechanicalReduction>1</mechanicalReduction>
    </actuator>
</transmission>

       <!-- iron_roughneck controller -->
    <transmission name="tran3">
        <type>transmission_interface/SimpleTransmission</type>
        <joint name="joint15">
            <hardwareInterface>hardware_interface/EffortJointInterface</hardwareInterface>
        </joint>        <!--using position joint interface now for the topdrive position-->
        <actuator name="motor3">
            <hardwareInterface>hardware_interface/EffortJointInterface</hardwareInterface>
            <mechanicalReduction>1</mechanicalReduction>
        </actuator>
    </transmission>
</robot> 